Workbook

Sheet Inicio
A1: Sistema de Gestión de Compras, Seguimiento y KPI
A2: Libro de control para el Analista de Compras: seguimiento documentario, reportabilidad, gestión de compras y KPI.
A4: CÓMO USAR
A5: Celdas amarillas / texto azul | B5: Datos que usted ingresa. Todo lo demás (texto negro) son fórmulas: no las sobrescriba.
A6: Fila de ejemplo | B6: Cada hoja de registro trae 1–3 filas de ejemplo con valores ficticios. Bórrelas o reemplácelas con sus datos reales.
A7: S / N / NA | B7: Los controles de sí/no usan listas desplegables: S = Sí, N = No, NA = No aplica.
A9: HOJA | B9: FUNCIÓN QUE CUBRE
A10: Parametros | B10: Año de análisis, centros, familias, proveedores, procedimientos y metas de KPI (editar primero).
A11: Requerimientos | B11: GESTIÓN DE COMPRAS: recepción y consolidado de requerimientos del mes, desagregado por familia y centro.
A12: Comparativo | B12: REPORTABILIDAD / GESTIÓN: cotizaciones de hasta 3 proveedores, cuadro comparativo, mejor precio y ahorro por negociación.
A13: Seguimiento_OC | B13: SEGUIMIENTO Y CONTROL DOCUMENTARIO: entrega en fecha, conformidad, registro sanitario, OC + guía + factura, envío a Chimbote según packing list, reprogramación, recepción por centro, importe facturado vs OC/cotización, registro en Kontrollers, crédito/contado, transporte.
A14: Produccion | B14: Análisis de producción: sesiones y costo por sesión por procedimiento, por mes.
A15: Consumos | B15: Análisis de consumos por centro por mes y consolidado anual.
A16: Reportes | B16: Resúmenes automáticos: compras por mes, crédito vs contado, por familia, ahorro, producción y consumo anual.
A17: KPI | B17: Tablero de KPI de Compras (automático), Almacén y Lavandería (ingreso mensual) con semáforo vs meta.

Sheet Parametros
A1: Parámetros
A2: Edite las listas (amarillo). Alimentan las listas desplegables y los reportes.
A4: Año de análisis | B4: 2026 | C4: Año usado por Reportes, Consumos y KPI.
A6: Centros | B6: Familias | C6: Proveedores | D6: Procedimientos | E6: Condicion | F6: SN | G6: Meses
A7: Lima - Sede Central | B7: Material médico | C7: Proveedor A SAC | D7: Hemodiálisis | E7: Crédito | F7: S | G7: Ene
A8: Chimbote | B8: Medicamentos | C8: Proveedor B EIRL | D8: Procedimiento 2 | E8: Contado | F8: N | G8: Feb
A9: Trujillo | B9: Insumos de laboratorio | C9: Proveedor C SA | D9: Procedimiento 3 | F9: NA | G9: Mar
A10: Chiclayo | B10: Limpieza y desinfección | C10: Proveedor D SAC | G10: Abr
A11: Piura | B11: Ropa y lavandería | G11: May
B12: Oficina | G12: Jun
B13: Mantenimiento | G13: Jul
G14: Ago
G15: Set
G16: Oct
G17: Nov
G18: Dic

Sheet Requerimientos
A1: Requerimientos del mes
A2: Consolidado de requerimientos recibidos de cada centro. Mes se calcula de la fecha de recepción.
A4: Fecha recepción | B4: Mes | C4: Centro solicitante | D4: Familia | E4: Código | F4: Descripción del ítem | G4: Unidad | H4: Cantidad requerida | I4: Fecha requerida | J4: N° OC asignada | K4: Estado | L4: Observaciones
A5: 46296 | B5: =IF(A5="","",MONTH(A5)) -> 10 | C5: Chimbote | D5: Material médico | E5: MM-001 | F5: Guantes de nitrilo talla M (caja x100) | G5: CAJA | H5: 120 | I5: 46305 | J5: OC-2026-0001 | K5: =IF(F5="","",IF(J5="","Pendiente OC",IF(COUNTIF(Seguimiento_OC!$A:$A,J5)=0,"OC no registrada",INDEX(Seguimiento_OC!$Y:$Y,MATCH(J5,Seguimiento_OC!$A:$A,0))))) -> Completa
A6: 46296 | B6: =IF(A6="","",MONTH(A6)) -> 10 | C6: Trujillo | D6: Limpieza y desinfección | E6: LD-014 | F6: Alcohol 70° x 1L | G6: UND | H6: 80 | I6: 46307 | K6: =IF(F6="","",IF(J6="","Pendiente OC",IF(COUNTIF(Seguimiento_OC!$A:$A,J6)=0,"OC no registrada",INDEX(Seguimiento_OC!$Y:$Y,MATCH(J6,Seguimiento_OC!$A:$A,0))))) -> Pendiente OC
A7: 46297 | B7: =IF(A7="","",MONTH(A7)) -> 10 | C7: Lima - Sede Central | D7: Medicamentos | E7: ME-120 | F7: Heparina sódica 5000 UI | G7: AMP | H7: 300 | I7: 46304 | J7: OC-2026-0002 | K7: =IF(F7="","",IF(J7="","Pendiente OC",IF(COUNTIF(Seguimiento_OC!$A:$A,J7)=0,"OC no registrada",INDEX(Seguimiento_OC!$Y:$Y,MATCH(J7,Seguimiento_OC!$A:$A,0))))) -> Parcial
B8: =IF(A8="","",MONTH(A8)) | K8: =IF(F8="","",IF(J8="","Pendiente OC",IF(COUNTIF(Seguimiento_OC!$A:$A,J8)=0,"OC no registrada",INDEX(Seguimiento_OC!$Y:$Y,MATCH(J8,Seguimiento_OC!$A:$A,0)))))
B9: =IF(A9="","",MONTH(A9)) | K9: =IF(F9="","",IF(J9="","Pendiente OC",IF(COUNTIF(Seguimiento_OC!$A:$A,J9)=0,"OC no registrada",INDEX(Seguimiento_OC!$Y:$Y,MATCH(J9,Seguimiento_OC!$A:$A,0)))))
B10: =IF(A10="","",MONTH(A10)) | K10: =IF(F10="","",IF(J10="","Pendiente OC",IF(COUNTIF(Seguimiento_OC!$A:$A,J10)=0,"OC no registrada",INDEX(Seguimiento_OC!$Y:$Y,MATCH(J10,Seguimiento_OC!$A:$A,0)))))
B11: =IF(A11="","",MONTH(A11)) | K11: =IF(F11="","",IF(J11="","Pendiente OC",IF(COUNTIF(Seguimiento_OC!$A:$A,J11)=0,"OC no registrada",INDEX(Seguimiento_OC!$Y:$Y,MATCH(J11,Seguimiento_OC!$A:$A,0)))))
B12: =IF(A12="","",MONTH(A12)) | K12: =IF(F12="","",IF(J12="","Pendiente OC",IF(COUNTIF(Seguimiento_OC!$A:$A,J12)=0,"OC no registrada",INDEX(Seguimiento_OC!$Y:$Y,MATCH(J12,Seguimiento_OC!$A:$A,0)))))
B13: =IF(A13="","",MONTH(A13)) | K13: =IF(F13="","",IF(J13="","Pendiente OC",IF(COUNTIF(Seguimiento_OC!$A:$A,J13)=0,"OC no registrada",INDEX(Seguimiento_OC!$Y:$Y,MATCH(J13,Seguimiento_OC!$A:$A,0)))))
B14: =IF(A14="","",MONTH(A14)) | K14: =IF(F14="","",IF(J14="","Pendiente OC",IF(COUNTIF(Seguimiento_OC!$A:$A,J14)=0,"OC no registrada",INDEX(Seguimiento_OC!$Y:$Y,MATCH(J14,Seguimiento_OC!$A:$A,0)))))
B15: =IF(A15="","",MONTH(A15)) | K15: =IF(F15="","",IF(J15="","Pendiente OC",IF(COUNTIF(Seguimiento_OC!$A:$A,J15)=0,"OC no registrada",INDEX(Seguimiento_OC!$Y:$Y,MATCH(J15,Seguimiento_OC!$A:$A,0)))))
B16: =IF(A16="","",MONTH(A16)) | K16: =IF(F16="","",IF(J16="","Pendiente OC",IF(COUNTIF(Seguimiento_OC!$A:$A,J16)=0,"OC no registrada",INDEX(Seguimiento_OC!$Y:$Y,MATCH(J16,Seguimiento_OC!$A:$A,0)))))
B17: =IF(A17="","",MONTH(A17)) | K17: =IF(F17="","",IF(J17="","Pendiente OC",IF(COUNTIF(Seguimiento_OC!$A:$A,J17)=0,"OC no registrada",INDEX(Seguimiento_OC!$Y:$Y,MATCH(J17,Seguimiento_OC!$A:$A,0)))))
B18: =IF(A18="","",MONTH(A18)) | K18: =IF(F18="","",IF(J18="","Pendiente OC",IF(COUNTIF(Seguimiento_OC!$A:$A,J18)=0,"OC no registrada",INDEX(Seguimiento_OC!$Y:$Y,MATCH(J18,Seguimiento_OC!$A:$A,0)))))
B19: =IF(A19="","",MONTH(A19)) | K19: =IF(F19="","",IF(J19="","Pendiente OC",IF(COUNTIF(Seguimiento_OC!$A:$A,J19)=0,"OC no registrada",INDEX(Seguimiento_OC!$Y:$Y,MATCH(J19,Seguimiento_OC!$A:$A,0)))))
... B304: =IF(A304="","",MONTH(A304)) | K304: =IF(F304="","",IF(J304="","Pendiente OC",IF(COUNTIF(Seguimiento_OC!$A:$A,J304)=0,"OC no registrada",INDEX(Seguimiento_OC!$Y:$Y,MATCH(J304,Seguimiento_OC!$A:$A,0)))))

Sheet Comparativo
A1: Cotizaciones y cuadro comparativo
A2: Ingrese precio unitario (sin IGV) de cada proveedor cotizado. Precio referencia = último precio pagado / año anterior.
A4: N° solicitud | B4: Fecha | C4: Familia | D4: Descripción del ítem | E4: Unidad | F4: Cantidad | G4: Proveedor 1 | H4: Precio unit. P1 (S/) | I4: Proveedor 2 | J4: Precio unit. P2 (S/) | K4: Proveedor 3 | L4: Precio unit. P3 (S/) | M4: Mejor precio (S/) | N4: Mejor proveedor | O4: Total mejor oferta (S/) | P4: Precio referencia (S/) | Q4: Precio negociado final (S/) | R4: Ahorro unitario (S/) | S4: Ahorro total (S/) | T4: % ahorro | U4: Proveedor adjudicado
A5: COT-001 | B5: 46298 | C5: Material médico | D5: Guantes de nitrilo talla M (caja x100) | E5: CAJA | F5: 120 | G5: Proveedor A SAC | H5: 24.5 | I5: Proveedor B EIRL | J5: 23.9 | K5: Proveedor C SA | L5: 25.1 | M5: =IF(COUNT(H5,J5,L5)=0,"",MIN(H5,J5,L5)) -> 23.9 | N5: =IF(M5="","",IF(H5=M5,G5,IF(J5=M5,I5,K5))) -> Proveedor B EIRL | O5: =IF(M5="","",M5*F5) -> 2868 | P5: 26 | Q5: 23.5 | R5: =IF(OR(P5="",Q5=""),"",P5-Q5) -> 2.5 | S5: =IF(R5="","",R5*F5) -> 300 | T5: =IF(OR(R5="",P5=0),"",R5/P5) -> 0.096153846 | U5: Proveedor B EIRL
A6: COT-002 | B6: 46298 | C6: Limpieza y desinfección | D6: Alcohol 70° x 1L | E6: UND | F6: 80 | G6: Proveedor C SA | H6: 6.8 | I6: Proveedor D SAC | J6: 7.1 | M6: =IF(COUNT(H6,J6,L6)=0,"",MIN(H6,J6,L6)) -> 6.8 | N6: =IF(M6="","",IF(H6=M6,G6,IF(J6=M6,I6,K6))) -> Proveedor C SA | O6: =IF(M6="","",M6*F6) -> 544 | P6: 7.2 | Q6: 6.7 | R6: =IF(OR(P6="",Q6=""),"",P6-Q6) -> 0.5 | S6: =IF(R6="","",R6*F6) -> 40 | T6: =IF(OR(R6="",P6=0),"",R6/P6) -> 0.069444444 | U6: Proveedor C SA
M7: =IF(COUNT(H7,J7,L7)=0,"",MIN(H7,J7,L7)) | N7: =IF(M7="","",IF(H7=M7,G7,IF(J7=M7,I7,K7))) | O7: =IF(M7="","",M7*F7) | R7: =IF(OR(P7="",Q7=""),"",P7-Q7) | S7: =IF(R7="","",R7*F7) | T7: =IF(OR(R7="",P7=0),"",R7/P7)
M8: =IF(COUNT(H8,J8,L8)=0,"",MIN(H8,J8,L8)) | N8: =IF(M8="","",IF(H8=M8,G8,IF(J8=M8,I8,K8))) | O8: =IF(M8="","",M8*F8) | R8: =IF(OR(P8="",Q8=""),"",P8-Q8) | S8: =IF(R8="","",R8*F8) | T8: =IF(OR(R8="",P8=0),"",R8/P8)
M9: =IF(COUNT(H9,J9,L9)=0,"",MIN(H9,J9,L9)) | N9: =IF(M9="","",IF(H9=M9,G9,IF(J9=M9,I9,K9))) | O9: =IF(M9="","",M9*F9) | R9: =IF(OR(P9="",Q9=""),"",P9-Q9) | S9: =IF(R9="","",R9*F9) | T9: =IF(OR(R9="",P9=0),"",R9/P9)
M10: =IF(COUNT(H10,J10,L10)=0,"",MIN(H10,J10,L10)) | N10: =IF(M10="","",IF(H10=M10,G10,IF(J10=M10,I10,K10))) | O10: =IF(M10="","",M10*F10) | R10: =IF(OR(P10="",Q10=""),"",P10-Q10) | S10: =IF(R10="","",R10*F10) | T10: =IF(OR(R10="",P10=0),"",R10/P10)
M11: =IF(COUNT(H11,J11,L11)=0,"",MIN(H11,J11,L11)) | N11: =IF(M11="","",IF(H11=M11,G11,IF(J11=M11,I11,K11))) | O11: =IF(M11="","",M11*F11) | R11: =IF(OR(P11="",Q11=""),"",P11-Q11) | S11: =IF(R11="","",R11*F11) | T11: =IF(OR(R11="",P11=0),"",R11/P11)
M12: =IF(COUNT(H12,J12,L12)=0,"",MIN(H12,J12,L12)) | N12: =IF(M12="","",IF(H12=M12,G12,IF(J12=M12,I12,K12))) | O12: =IF(M12="","",M12*F12) | R12: =IF(OR(P12="",Q12=""),"",P12-Q12) | S12: =IF(R12="","",R12*F12) | T12: =IF(OR(R12="",P12=0),"",R12/P12)
M13: =IF(COUNT(H13,J13,L13)=0,"",MIN(H13,J13,L13)) | N13: =IF(M13="","",IF(H13=M13,G13,IF(J13=M13,I13,K13))) | O13: =IF(M13="","",M13*F13) | R13: =IF(OR(P13="",Q13=""),"",P13-Q13) | S13: =IF(R13="","",R13*F13) | T13: =IF(OR(R13="",P13=0),"",R13/P13)
M14: =IF(COUNT(H14,J14,L14)=0,"",MIN(H14,J14,L14)) | N14: =IF(M14="","",IF(H14=M14,G14,IF(J14=M14,I14,K14))) | O14: =IF(M14="","",M14*F14) | R14: =IF(OR(P14="",Q14=""),"",P14-Q14) | S14: =IF(R14="","",R14*F14) | T14: =IF(OR(R14="",P14=0),"",R14/P14)
M15: =IF(COUNT(H15,J15,L15)=0,"",MIN(H15,J15,L15)) | N15: =IF(M15="","",IF(H15=M15,G15,IF(J15=M15,I15,K15))) | O15: =IF(M15="","",M15*F15) | R15: =IF(OR(P15="",Q15=""),"",P15-Q15) | S15: =IF(R15="","",R15*F15) | T15: =IF(OR(R15="",P15=0),"",R15/P15)
M16: =IF(COUNT(H16,J16,L16)=0,"",MIN(H16,J16,L16)) | N16: =IF(M16="","",IF(H16=M16,G16,IF(J16=M16,I16,K16))) | O16: =IF(M16="","",M16*F16) | R16: =IF(OR(P16="",Q16=""),"",P16-Q16) | S16: =IF(R16="","",R16*F16) | T16: =IF(OR(R16="",P16=0),"",R16/P16)
M17: =IF(COUNT(H17,J17,L17)=0,"",MIN(H17,J17,L17)) | N17: =IF(M17="","",IF(H17=M17,G17,IF(J17=M17,I17,K17))) | O17: =IF(M17="","",M17*F17) | R17: =IF(OR(P17="",Q17=""),"",P17-Q17) | S17: =IF(R17="","",R17*F17) | T17: =IF(OR(R17="",P17=0),"",R17/P17)
M18: =IF(COUNT(H18,J18,L18)=0,"",MIN(H18,J18,L18)) | N18: =IF(M18="","",IF(H18=M18,G18,IF(J18=M18,I18,K18))) | O18: =IF(M18="","",M18*F18) | R18: =IF(OR(P18="",Q18=""),"",P18-Q18) | S18: =IF(R18="","",R18*F18) | T18: =IF(OR(R18="",P18=0),"",R18/P18)
... M304: =IF(COUNT(H304,J304,L304)=0,"",MIN(H304,J304,L304)) | N304: =IF(M304="","",IF(H304=M304,G304,IF(J304=M304,I304,K304))) | O304: =IF(M304="","",M304*F304) | R304: =IF(OR(P304="",Q304=""),"",P304-Q304) | S304: =IF(R304="","",R304*F304) | T304: =IF(OR(R304="",P304=0),"",R304/P304)

Sheet Seguimiento_OC
A1: Seguimiento y control documentario de Órdenes de Compra
A2: Una fila por OC y centro de destino. Columnas Q–Y y AB–AD se calculan solas.
A4: N° OC | B4: Fecha emisión OC | C4: Proveedor | D4: Familia | E4: Centro destino | F4: Condición pago | G4: Monto OC (S/) | H4: Fecha entrega programada | I4: Fecha entrega real | J4: Cantidad pedida | K4: Cantidad recibida | L4: Producto conforme al pedido (S/N) | M4: Registro sanitario vigente (S/N/NA) | N4: Entregó OC (S/N) | O4: Entregó guía (S/N) | P4: Entregó factura (S/N) | Q4: Mes emisión | R4: % atención | S4: Días de retraso | T4: Entrega a tiempo | U4: Documentos completos | V4: Envío según packing list a Chimbote (S/N/NA) | W4: Monto factura (S/) | X4: Diferencia factura vs OC (S/) | Y4: Estado | Z4: Nueva fecha reprogramada | AA4: Transporte / agencia | AB4: Control importe | AC4: Registrado en Kontrollers (S/N) | AD4: Acción requerida | AE4: Observaciones
A5: OC-2026-0001 | B5: 46299 | C5: Proveedor B EIRL | D5: Material médico | E5: Chimbote | F5: Crédito | G5: 3384.84 | H5: 46305 | I5: 46305 | J5: 120 | K5: 120 | L5: S | M5: S | N5: S | O5: S | P5: S | Q5: =IF(B5="","",MONTH(B5)) -> 10 | R5: =IF(OR(J5="",J5=0),"",MIN(1,K5/J5)) -> 1 | S5: =IF(H5="","",IF(I5="",MAX(0,TODAY()-H5),MAX(0,I5-H5))) -> 0 | T5: =IF(OR(H5="",I5=""),"",IF(I5<=H5,"S","N")) -> S | U5: =IF(A5="","",IF(AND(N5="S",O5="S",P5="S"),"S","N")) -> S | V5: S | W5: 3384.84 | X5: =IF(W5="","",W5-G5) -> 0 | Y5: =IF(A5="","",IF(K5=0,IF(AND(H5<>"",TODAY()>H5),"Vencida","Pendiente"),IF(K5<J5,"Parcial","Completa"))) -> Completa | AA5: Transportes Ejemplo | AB5: =IF(W5="","Sin factura",IF(ABS(X5)<=0.01,"OK","Revisar")) -> OK | AC5: S | AD5: =IF(A5="","",IF(L5="N","Producto no conforme",IF(M5="N","Falta registro sanitario",IF(OR(Y5="Parcial",Y5="Vencida"),IF(Z5="","Reprogramar recepción","Reprogramada "&TEXT(Z5,"dd/mm")),IF(Y5="Pendiente","En espera",IF(U5="N","Completar documentos",IF(AB5="Revisar","Revisar importe facturado",IF(AC5<>"S","Registrar en Kontrollers","OK")))))))) -> OK
A6: OC-2026-0002 | B6: 46299 | C6: Proveedor A SAC | D6: Medicamentos | E6: Lima - Sede Central | F6: Contado | G6: 5310 | H6: 46304 | I6: 46306 | J6: 300 | K6: 180 | L6: S | M6: S | N6: S | O6: S | P6: N | Q6: =IF(B6="","",MONTH(B6)) -> 10 | R6: =IF(OR(J6="",J6=0),"",MIN(1,K6/J6)) -> 0.6 | S6: =IF(H6="","",IF(I6="",MAX(0,TODAY()-H6),MAX(0,I6-H6))) -> 2 | T6: =IF(OR(H6="",I6=""),"",IF(I6<=H6,"S","N")) -> N | U6: =IF(A6="","",IF(AND(N6="S",O6="S",P6="S"),"S","N")) -> N | V6: NA | X6: =IF(W6="","",W6-G6) | Y6: =IF(A6="","",IF(K6=0,IF(AND(H6<>"",TODAY()>H6),"Vencida","Pendiente"),IF(K6<J6,"Parcial","Completa"))) -> Parcial | Z6: 46311 | AA6: Propio | AB6: =IF(W6="","Sin factura",IF(ABS(X6)<=0.01,"OK","Revisar")) -> Sin factura | AC6: N | AD6: =IF(A6="","",IF(L6="N","Producto no conforme",IF(M6="N","Falta registro sanitario",IF(OR(Y6="Parcial",Y6="Vencida"),IF(Z6="","Reprogramar recepción","Reprogramada "&TEXT(Z6,"dd/mm")),IF(Y6="Pendiente","En espera",IF(U6="N","Completar documentos",IF(AB6="Revisar","Revisar importe facturado",IF(AC6<>"S","Registrar en Kontrollers","OK")))))))) -> Reprogramada 16/10 | AE6: Entrega parcial; falta factura
A7: OC-2026-0003 | B7: 46300 | C7: Proveedor C SA | D7: Limpieza y desinfección | E7: Trujillo | F7: Crédito | G7: 632.48 | H7: 46307 | J7: 80 | K7: 0 | Q7: =IF(B7="","",MONTH(B7)) -> 10 | R7: =IF(OR(J7="",J7=0),"",MIN(1,K7/J7)) -> 0 | S7: =IF(H7="","",IF(I7="",MAX(0,TODAY()-H7),MAX(0,I7-H7))) -> 0 | T7: =IF(OR(H7="",I7=""),"",IF(I7<=H7,"S","N")) | U7: =IF(A7="","",IF(AND(N7="S",O7="S",P7="S"),"S","N")) -> N | V7: NA | X7: =IF(W7="","",W7-G7) | Y7: =IF(A7="","",IF(K7=0,IF(AND(H7<>"",TODAY()>H7),"Vencida","Pendiente"),IF(K7<J7,"Parcial","Completa"))) -> Pendiente | AA7: Transportes Ejemplo | AB7: =IF(W7="","Sin factura",IF(ABS(X7)<=0.01,"OK","Revisar")) -> Sin factura | AC7: N | AD7: =IF(A7="","",IF(L7="N","Producto no conforme",IF(M7="N","Falta registro sanitario",IF(OR(Y7="Parcial",Y7="Vencida"),IF(Z7="","Reprogramar recepción","Reprogramada "&TEXT(Z7,"dd/mm")),IF(Y7="Pendiente","En espera",IF(U7="N","Completar documentos",IF(AB7="Revisar","Revisar importe facturado",IF(AC7<>"S","Registrar en Kontrollers","OK")))))))) -> En espera
Q8: =IF(B8="","",MONTH(B8)) | R8: =IF(OR(J8="",J8=0),"",MIN(1,K8/J8)) | S8: =IF(H8="","",IF(I8="",MAX(0,TODAY()-H8),MAX(0,I8-H8))) | T8: =IF(OR(H8="",I8=""),"",IF(I8<=H8,"S","N")) | U8: =IF(A8="","",IF(AND(N8="S",O8="S",P8="S"),"S","N")) | X8: =IF(W8="","",W8-G8) | Y8: =IF(A8="","",IF(K8=0,IF(AND(H8<>"",TODAY()>H8),"Vencida","Pendiente"),IF(K8<J8,"Parcial","Completa"))) | AB8: =IF(W8="","Sin factura",IF(ABS(X8)<=0.01,"OK","Revisar")) -> Sin factura | AD8: =IF(A8="","",IF(L8="N","Producto no conforme",IF(M8="N","Falta registro sanitario",IF(OR(Y8="Parcial",Y8="Vencida"),IF(Z8="","Reprogramar recepción","Reprogramada "&TEXT(Z8,"dd/mm")),IF(Y8="Pendiente","En espera",IF(U8="N","Completar documentos",IF(AB8="Revisar","Revisar importe facturado",IF(AC8<>"S","Registrar en Kontrollers","OK"))))))))
Q9: =IF(B9="","",MONTH(B9)) | R9: =IF(OR(J9="",J9=0),"",MIN(1,K9/J9)) | S9: =IF(H9="","",IF(I9="",MAX(0,TODAY()-H9),MAX(0,I9-H9))) | T9: =IF(OR(H9="",I9=""),"",IF(I9<=H9,"S","N")) | U9: =IF(A9="","",IF(AND(N9="S",O9="S",P9="S"),"S","N")) | X9: =IF(W9="","",W9-G9) | Y9: =IF(A9="","",IF(K9=0,IF(AND(H9<>"",TODAY()>H9),"Vencida","Pendiente"),IF(K9<J9,"Parcial","Completa"))) | AB9: =IF(W9="","Sin factura",IF(ABS(X9)<=0.01,"OK","Revisar")) -> Sin factura | AD9: =IF(A9="","",IF(L9="N","Producto no conforme",IF(M9="N","Falta registro sanitario",IF(OR(Y9="Parcial",Y9="Vencida"),IF(Z9="","Reprogramar recepción","Reprogramada "&TEXT(Z9,"dd/mm")),IF(Y9="Pendiente","En espera",IF(U9="N","Completar documentos",IF(AB9="Revisar","Revisar importe facturado",IF(AC9<>"S","Registrar en Kontrollers","OK"))))))))
Q10: =IF(B10="","",MONTH(B10)) | R10: =IF(OR(J10="",J10=0),"",MIN(1,K10/J10)) | S10: =IF(H10="","",IF(I10="",MAX(0,TODAY()-H10),MAX(0,I10-H10))) | T10: =IF(OR(H10="",I10=""),"",IF(I10<=H10,"S","N")) | U10: =IF(A10="","",IF(AND(N10="S",O10="S",P10="S"),"S","N")) | X10: =IF(W10="","",W10-G10) | Y10: =IF(A10="","",IF(K10=0,IF(AND(H10<>"",TODAY()>H10),"Vencida","Pendiente"),IF(K10<J10,"Parcial","Completa"))) | AB10: =IF(W10="","Sin factura",IF(ABS(X10)<=0.01,"OK","Revisar")) -> Sin factura | AD10: =IF(A10="","",IF(L10="N","Producto no conforme",IF(M10="N","Falta registro sanitario",IF(OR(Y10="Parcial",Y10="Vencida"),IF(Z10="","Reprogramar recepción","Reprogramada "&TEXT(Z10,"dd/mm")),IF(Y10="Pendiente","En espera",IF(U10="N","Completar documentos",IF(AB10="Revisar","Revisar importe facturado",IF(AC10<>"S","Registrar en Kontrollers","OK"))))))))
Q11: =IF(B11="","",MONTH(B11)) | R11: =IF(OR(J11="",J11=0),"",MIN(1,K11/J11)) | S11: =IF(H11="","",IF(I11="",MAX(0,TODAY()-H11),MAX(0,I11-H11))) | T11: =IF(OR(H11="",I11=""),"",IF(I11<=H11,"S","N")) | U11: =IF(A11="","",IF(AND(N11="S",O11="S",P11="S"),"S","N")) | X11: =IF(W11="","",W11-G11) | Y11: =IF(A11="","",IF(K11=0,IF(AND(H11<>"",TODAY()>H11),"Vencida","Pendiente"),IF(K11<J11,"Parcial","Completa"))) | AB11: =IF(W11="","Sin factura",IF(ABS(X11)<=0.01,"OK","Revisar")) -> Sin factura | AD11: =IF(A11="","",IF(L11="N","Producto no conforme",IF(M11="N","Falta registro sanitario",IF(OR(Y11="Parcial",Y11="Vencida"),IF(Z11="","Reprogramar recepción","Reprogramada "&TEXT(Z11,"dd/mm")),IF(Y11="Pendiente","En espera",IF(U11="N","Completar documentos",IF(AB11="Revisar","Revisar importe facturado",IF(AC11<>"S","Registrar en Kontrollers","OK"))))))))
Q12: =IF(B12="","",MONTH(B12)) | R12: =IF(OR(J12="",J12=0),"",MIN(1,K12/J12)) | S12: =IF(H12="","",IF(I12="",MAX(0,TODAY()-H12),MAX(0,I12-H12))) | T12: =IF(OR(H12="",I12=""),"",IF(I12<=H12,"S","N")) | U12: =IF(A12="","",IF(AND(N12="S",O12="S",P12="S"),"S","N")) | X12: =IF(W12="","",W12-G12) | Y12: =IF(A12="","",IF(K12=0,IF(AND(H12<>"",TODAY()>H12),"Vencida","Pendiente"),IF(K12<J12,"Parcial","Completa"))) | AB12: =IF(W12="","Sin factura",IF(ABS(X12)<=0.01,"OK","Revisar")) -> Sin factura | AD12: =IF(A12="","",IF(L12="N","Producto no conforme",IF(M12="N","Falta registro sanitario",IF(OR(Y12="Parcial",Y12="Vencida"),IF(Z12="","Reprogramar recepción","Reprogramada "&TEXT(Z12,"dd/mm")),IF(Y12="Pendiente","En espera",IF(U12="N","Completar documentos",IF(AB12="Revisar","Revisar importe facturado",IF(AC12<>"S","Registrar en Kontrollers","OK"))))))))
Q13: =IF(B13="","",MONTH(B13)) | R13: =IF(OR(J13="",J13=0),"",MIN(1,K13/J13)) | S13: =IF(H13="","",IF(I13="",MAX(0,TODAY()-H13),MAX(0,I13-H13))) | T13: =IF(OR(H13="",I13=""),"",IF(I13<=H13,"S","N")) | U13: =IF(A13="","",IF(AND(N13="S",O13="S",P13="S"),"S","N")) | X13: =IF(W13="","",W13-G13) | Y13: =IF(A13="","",IF(K13=0,IF(AND(H13<>"",TODAY()>H13),"Vencida","Pendiente"),IF(K13<J13,"Parcial","Completa"))) | AB13: =IF(W13="","Sin factura",IF(ABS(X13)<=0.01,"OK","Revisar")) -> Sin factura | AD13: =IF(A13="","",IF(L13="N","Producto no conforme",IF(M13="N","Falta registro sanitario",IF(OR(Y13="Parcial",Y13="Vencida"),IF(Z13="","Reprogramar recepción","Reprogramada "&TEXT(Z13,"dd/mm")),IF(Y13="Pendiente","En espera",IF(U13="N","Completar documentos",IF(AB13="Revisar","Revisar importe facturado",IF(AC13<>"S","Registrar en Kontrollers","OK"))))))))
Q14: =IF(B14="","",MONTH(B14)) | R14: =IF(OR(J14="",J14=0),"",MIN(1,K14/J14)) | S14: =IF(H14="","",IF(I14="",MAX(0,TODAY()-H14),MAX(0,I14-H14))) | T14: =IF(OR(H14="",I14=""),"",IF(I14<=H14,"S","N")) | U14: =IF(A14="","",IF(AND(N14="S",O14="S",P14="S"),"S","N")) | X14: =IF(W14="","",W14-G14) | Y14: =IF(A14="","",IF(K14=0,IF(AND(H14<>"",TODAY()>H14),"Vencida","Pendiente"),IF(K14<J14,"Parcial","Completa"))) | AB14: =IF(W14="","Sin factura",IF(ABS(X14)<=0.01,"OK","Revisar")) -> Sin factura | AD14: =IF(A14="","",IF(L14="N","Producto no conforme",IF(M14="N","Falta registro sanitario",IF(OR(Y14="Parcial",Y14="Vencida"),IF(Z14="","Reprogramar recepción","Reprogramada "&TEXT(Z14,"dd/mm")),IF(Y14="Pendiente","En espera",IF(U14="N","Completar documentos",IF(AB14="Revisar","Revisar importe facturado",IF(AC14<>"S","Registrar en Kontrollers","OK"))))))))
Q15: =IF(B15="","",MONTH(B15)) | R15: =IF(OR(J15="",J15=0),"",MIN(1,K15/J15)) | S15: =IF(H15="","",IF(I15="",MAX(0,TODAY()-H15),MAX(0,I15-H15))) | T15: =IF(OR(H15="",I15=""),"",IF(I15<=H15,"S","N")) | U15: =IF(A15="","",IF(AND(N15="S",O15="S",P15="S"),"S","N")) | X15: =IF(W15="","",W15-G15) | Y15: =IF(A15="","",IF(K15=0,IF(AND(H15<>"",TODAY()>H15),"Vencida","Pendiente"),IF(K15<J15,"Parcial","Completa"))) | AB15: =IF(W15="","Sin factura",IF(ABS(X15)<=0.01,"OK","Revisar")) -> Sin factura | AD15: =IF(A15="","",IF(L15="N","Producto no conforme",IF(M15="N","Falta registro sanitario",IF(OR(Y15="Parcial",Y15="Vencida"),IF(Z15="","Reprogramar recepción","Reprogramada "&TEXT(Z15,"dd/mm")),IF(Y15="Pendiente","En espera",IF(U15="N","Completar documentos",IF(AB15="Revisar","Revisar importe facturado",IF(AC15<>"S","Registrar en Kontrollers","OK"))))))))
Q16: =IF(B16="","",MONTH(B16)) | R16: =IF(OR(J16="",J16=0),"",MIN(1,K16/J16)) | S16: =IF(H16="","",IF(I16="",MAX(0,TODAY()-H16),MAX(0,I16-H16))) | T16: =IF(OR(H16="",I16=""),"",IF(I16<=H16,"S","N")) | U16: =IF(A16="","",IF(AND(N16="S",O16="S",P16="S"),"S","N")) | X16: =IF(W16="","",W16-G16) | Y16: =IF(A16="","",IF(K16=0,IF(AND(H16<>"",TODAY()>H16),"Vencida","Pendiente"),IF(K16<J16,"Parcial","Completa"))) | AB16: =IF(W16="","Sin factura",IF(ABS(X16)<=0.01,"OK","Revisar")) -> Sin factura | AD16: =IF(A16="","",IF(L16="N","Producto no conforme",IF(M16="N","Falta registro sanitario",IF(OR(Y16="Parcial",Y16="Vencida"),IF(Z16="","Reprogramar recepción","Reprogramada "&TEXT(Z16,"dd/mm")),IF(Y16="Pendiente","En espera",IF(U16="N","Completar documentos",IF(AB16="Revisar","Revisar importe facturado",IF(AC16<>"S","Registrar en Kontrollers","OK"))))))))
Q17: =IF(B17="","",MONTH(B17)) | R17: =IF(OR(J17="",J17=0),"",MIN(1,K17/J17)) | S17: =IF(H17="","",IF(I17="",MAX(0,TODAY()-H17),MAX(0,I17-H17))) | T17: =IF(OR(H17="",I17=""),"",IF(I17<=H17,"S","N")) | U17: =IF(A17="","",IF(AND(N17="S",O17="S",P17="S"),"S","N")) | X17: =IF(W17="","",W17-G17) | Y17: =IF(A17="","",IF(K17=0,IF(AND(H17<>"",TODAY()>H17),"Vencida","Pendiente"),IF(K17<J17,"Parcial","Completa"))) | AB17: =IF(W17="","Sin factura",IF(ABS(X17)<=0.01,"OK","Revisar")) -> Sin factura | AD17: =IF(A17="","",IF(L17="N","Producto no conforme",IF(M17="N","Falta registro sanitario",IF(OR(Y17="Parcial",Y17="Vencida"),IF(Z17="","Reprogramar recepción","Reprogramada "&TEXT(Z17,"dd/mm")),IF(Y17="Pendiente","En espera",IF(U17="N","Completar documentos",IF(AB17="Revisar","Revisar importe facturado",IF(AC17<>"S","Registrar en Kontrollers","OK"))))))))
Q18: =IF(B18="","",MONTH(B18)) | R18: =IF(OR(J18="",J18=0),"",MIN(1,K18/J18)) | S18: =IF(H18="","",IF(I18="",MAX(0,TODAY()-H18),MAX(0,I18-H18))) | T18: =IF(OR(H18="",I18=""),"",IF(I18<=H18,"S","N")) | U18: =IF(A18="","",IF(AND(N18="S",O18="S",P18="S"),"S","N")) | X18: =IF(W18="","",W18-G18) | Y18: =IF(A18="","",IF(K18=0,IF(AND(H18<>"",TODAY()>H18),"Vencida","Pendiente"),IF(K18<J18,"Parcial","Completa"))) | AB18: =IF(W18="","Sin factura",IF(ABS(X18)<=0.01,"OK","Revisar")) -> Sin factura | AD18: =IF(A18="","",IF(L18="N","Producto no conforme",IF(M18="N","Falta registro sanitario",IF(OR(Y18="Parcial",Y18="Vencida"),IF(Z18="","Reprogramar recepción","Reprogramada "&TEXT(Z18,"dd/mm")),IF(Y18="Pendiente","En espera",IF(U18="N","Completar documentos",IF(AB18="Revisar","Revisar importe facturado",IF(AC18<>"S","Registrar en Kontrollers","OK"))))))))
Q19: =IF(B19="","",MONTH(B19)) | R19: =IF(OR(J19="",J19=0),"",MIN(1,K19/J19)) | S19: =IF(H19="","",IF(I19="",MAX(0,TODAY()-H19),MAX(0,I19-H19))) | T19: =IF(OR(H19="",I19=""),"",IF(I19<=H19,"S","N")) | U19: =IF(A19="","",IF(AND(N19="S",O19="S",P19="S"),"S","N")) | X19: =IF(W19="","",W19-G19) | Y19: =IF(A19="","",IF(K19=0,IF(AND(H19<>"",TODAY()>H19),"Vencida","Pendiente"),IF(K19<J19,"Parcial","Completa"))) | AB19: =IF(W19="","Sin factura",IF(ABS(X19)<=0.01,"OK","Revisar")) -> Sin factura | AD19: =IF(A19="","",IF(L19="N","Producto no conforme",IF(M19="N","Falta registro sanitario",IF(OR(Y19="Parcial",Y19="Vencida"),IF(Z19="","Reprogramar recepción","Reprogramada "&TEXT(Z19,"dd/mm")),IF(Y19="Pendiente","En espera",IF(U19="N","Completar documentos",IF(AB19="Revisar","Revisar importe facturado",IF(AC19<>"S","Registrar en Kontrollers","OK"))))))))
... Q304: =IF(B304="","",MONTH(B304)) | R304: =IF(OR(J304="",J304=0),"",MIN(1,K304/J304)) | S304: =IF(H304="","",IF(I304="",MAX(0,TODAY()-H304),MAX(0,I304-H304))) | T304: =IF(OR(H304="",I304=""),"",IF(I304<=H304,"S","N")) | U304: =IF(A304="","",IF(AND(N304="S",O304="S",P304="S"),"S","N")) | X304: =IF(W304="","",W304-G304) | Y304: =IF(A304="","",IF(K304=0,IF(AND(H304<>"",TODAY()>H304),"Vencida","Pendiente"),IF(K304<J304,"Parcial","Completa"))) | AB304: =IF(W304="","Sin factura",IF(ABS(X304)<=0.01,"OK","Revisar")) -> Sin factura | AD304: =IF(A304="","",IF(L304="N","Producto no conforme",IF(M304="N","Falta registro sanitario",IF(OR(Y304="Parcial",Y304="Vencida"),IF(Z304="","Reprogramar recepción","Reprogramada "&TEXT(Z304,"dd/mm")),IF(Y304="Pendiente","En espera",IF(U304="N","Completar documentos",IF(AB304="Revisar","Revisar importe facturado",IF(AC304<>"S","Registrar en Kontrollers","OK"))))))))

Sheet Produccion
A1: Producción y costo por sesión
A2: Una fila por mes, centro y procedimiento. Costo de insumos = consumo valorizado del mes para ese procedimiento.
A4: Año | B4: Mes (1-12) | C4: Centro | D4: Procedimiento | E4: N° sesiones | F4: Costo insumos (S/) | G4: Costo por sesión (S/)
A5: 2026 | B5: 9 | C5: Chimbote | D5: Hemodiálisis | E5: 1450 | F5: 98600 | G5: =IF(OR(E5="",E5=0),"",F5/E5) -> 68
A6: 2026 | B6: 9 | C6: Trujillo | D6: Hemodiálisis | E6: 1210 | F6: 84700 | G6: =IF(OR(E6="",E6=0),"",F6/E6) -> 70
A7: 2026 | B7: 10 | C7: Chimbote | D7: Hemodiálisis | E7: 1500 | F7: 100500 | G7: =IF(OR(E7="",E7=0),"",F7/E7) -> 67
G8: =IF(OR(E8="",E8=0),"",F8/E8)
G9: =IF(OR(E9="",E9=0),"",F9/E9)
G10: =IF(OR(E10="",E10=0),"",F10/E10)
G11: =IF(OR(E11="",E11=0),"",F11/E11)
G12: =IF(OR(E12="",E12=0),"",F12/E12)
G13: =IF(OR(E13="",E13=0),"",F13/E13)
G14: =IF(OR(E14="",E14=0),"",F14/E14)
G15: =IF(OR(E15="",E15=0),"",F15/E15)
G16: =IF(OR(E16="",E16=0),"",F16/E16)
G17: =IF(OR(E17="",E17=0),"",F17/E17)
G18: =IF(OR(E18="",E18=0),"",F18/E18)
G19: =IF(OR(E19="",E19=0),"",F19/E19)
... G304: =IF(OR(E304="",E304=0),"",F304/E304)

Sheet Consumos
A1: Consumos por centro
A2: Registro de salidas de almacén valorizadas. La matriz de la derecha consolida por centro y mes del año de análisis.
A4: Fecha salida | B4: Mes | C4: Año | D4: Centro | E4: Familia | F4: Descripción | G4: Cantidad | H4: Costo unit. (S/) | I4: Importe (S/) | K4: Centro / Mes | L4: Ene | M4: Feb | N4: Mar | O4: Abr | P4: May | Q4: Jun | R4: Jul | S4: Ago | T4: Set | U4: Oct | V4: Nov | W4: Dic | X4: Total año
A5: 46297 | B5: =IF(A5="","",MONTH(A5)) -> 10 | C5: =IF(A5="","",YEAR(A5)) -> 2026 | D5: Chimbote | E5: Material médico | F5: Guantes de nitrilo talla M | G5: 40 | H5: 23.5 | I5: =IF(G5="","",G5*H5) -> 940 | K5: =IF(Parametros!$A$7="","",Parametros!$A$7) -> Lima - Sede Central | L5: =IF($K5="","",SUMIFS($I$5:$I$304,$D$5:$D$304,$K5,$B$5:$B$304,1,$C$5:$C$304,Parametros!$B$4)) -> 0 | M5: =IF($K5="","",SUMIFS($I$5:$I$304,$D$5:$D$304,$K5,$B$5:$B$304,2,$C$5:$C$304,Parametros!$B$4)) -> 0 | N5: =IF($K5="","",SUMIFS($I$5:$I$304,$D$5:$D$304,$K5,$B$5:$B$304,3,$C$5:$C$304,Parametros!$B$4)) -> 0 | O5: =IF($K5="","",SUMIFS($I$5:$I$304,$D$5:$D$304,$K5,$B$5:$B$304,4,$C$5:$C$304,Parametros!$B$4)) -> 0 | P5: =IF($K5="","",SUMIFS($I$5:$I$304,$D$5:$D$304,$K5,$B$5:$B$304,5,$C$5:$C$304,Parametros!$B$4)) -> 0 | Q5: =IF($K5="","",SUMIFS($I$5:$I$304,$D$5:$D$304,$K5,$B$5:$B$304,6,$C$5:$C$304,Parametros!$B$4)) -> 0 | R5: =IF($K5="","",SUMIFS($I$5:$I$304,$D$5:$D$304,$K5,$B$5:$B$304,7,$C$5:$C$304,Parametros!$B$4)) -> 0 | S5: =IF($K5="","",SUMIFS($I$5:$I$304,$D$5:$D$304,$K5,$B$5:$B$304,8,$C$5:$C$304,Parametros!$B$4)) -> 0 | T5: =IF($K5="","",SUMIFS($I$5:$I$304,$D$5:$D$304,$K5,$B$5:$B$304,9,$C$5:$C$304,Parametros!$B$4)) -> 0 | U5: =IF($K5="","",SUMIFS($I$5:$I$304,$D$5:$D$304,$K5,$B$5:$B$304,10,$C$5:$C$304,Parametros!$B$4)) -> 0 | V5: =IF($K5="","",SUMIFS($I$5:$I$304,$D$5:$D$304,$K5,$B$5:$B$304,11,$C$5:$C$304,Parametros!$B$4)) -> 0 | W5: =IF($K5="","",SUMIFS($I$5:$I$304,$D$5:$D$304,$K5,$B$5:$B$304,12,$C$5:$C$304,Parametros!$B$4)) -> 0 | X5: =IF($K5="","",SUM(L5:W5)) -> 0
A6: 46298 | B6: =IF(A6="","",MONTH(A6)) -> 10 | C6: =IF(A6="","",YEAR(A6)) -> 2026 | D6: Trujillo | E6: Limpieza y desinfección | F6: Alcohol 70° x 1L | G6: 25 | H6: 6.7 | I6: =IF(G6="","",G6*H6) -> 167.5 | K6: =IF(Parametros!$A$8="","",Parametros!$A$8) -> Chimbote | L6: =IF($K6="","",SUMIFS($I$5:$I$304,$D$5:$D$304,$K6,$B$5:$B$304,1,$C$5:$C$304,Parametros!$B$4)) -> 0 | M6: =IF($K6="","",SUMIFS($I$5:$I$304,$D$5:$D$304,$K6,$B$5:$B$304,2,$C$5:$C$304,Parametros!$B$4)) -> 0 | N6: =IF($K6="","",SUMIFS($I$5:$I$304,$D$5:$D$304,$K6,$B$5:$B$304,3,$C$5:$C$304,Parametros!$B$4)) -> 0 | O6: =IF($K6="","",SUMIFS($I$5:$I$304,$D$5:$D$304,$K6,$B$5:$B$304,4,$C$5:$C$304,Parametros!$B$4)) -> 0 | P6: =IF($K6="","",SUMIFS($I$5:$I$304,$D$5:$D$304,$K6,$B$5:$B$304,5,$C$5:$C$304,Parametros!$B$4)) -> 0 | Q6: =IF($K6="","",SUMIFS($I$5:$I$304,$D$5:$D$304,$K6,$B$5:$B$304,6,$C$5:$C$304,Parametros!$B$4)) -> 0 | R6: =IF($K6="","",SUMIFS($I$5:$I$304,$D$5:$D$304,$K6,$B$5:$B$304,7,$C$5:$C$304,Parametros!$B$4)) -> 0 | S6: =IF($K6="","",SUMIFS($I$5:$I$304,$D$5:$D$304,$K6,$B$5:$B$304,8,$C$5:$C$304,Parametros!$B$4)) -> 0 | T6: =IF($K6="","",SUMIFS($I$5:$I$304,$D$5:$D$304,$K6,$B$5:$B$304,9,$C$5:$C$304,Parametros!$B$4)) -> 0 | U6: =IF($K6="","",SUMIFS($I$5:$I$304,$D$5:$D$304,$K6,$B$5:$B$304,10,$C$5:$C$304,Parametros!$B$4)) -> 940 | V6: =IF($K6="","",SUMIFS($I$5:$I$304,$D$5:$D$304,$K6,$B$5:$B$304,11,$C$5:$C$304,Parametros!$B$4)) -> 0 | W6: =IF($K6="","",SUMIFS($I$5:$I$304,$D$5:$D$304,$K6,$B$5:$B$304,12,$C$5:$C$304,Parametros!$B$4)) -> 0 | X6: =IF($K6="","",SUM(L6:W6)) -> 940
B7: =IF(A7="","",MONTH(A7)) | C7: =IF(A7="","",YEAR(A7)) | I7: =IF(G7="","",G7*H7) | K7: =IF(Parametros!$A$9="","",Parametros!$A$9) -> Trujillo | L7: =IF($K7="","",SUMIFS($I$5:$I$304,$D$5:$D$304,$K7,$B$5:$B$304,1,$C$5:$C$304,Parametros!$B$4)) -> 0 | M7: =IF($K7="","",SUMIFS($I$5:$I$304,$D$5:$D$304,$K7,$B$5:$B$304,2,$C$5:$C$304,Parametros!$B$4)) -> 0 | N7: =IF($K7="","",SUMIFS($I$5:$I$304,$D$5:$D$304,$K7,$B$5:$B$304,3,$C$5:$C$304,Parametros!$B$4)) -> 0 | O7: =IF($K7="","",SUMIFS($I$5:$I$304,$D$5:$D$304,$K7,$B$5:$B$304,4,$C$5:$C$304,Parametros!$B$4)) -> 0 | P7: =IF($K7="","",SUMIFS($I$5:$I$304,$D$5:$D$304,$K7,$B$5:$B$304,5,$C$5:$C$304,Parametros!$B$4)) -> 0 | Q7: =IF($K7="","",SUMIFS($I$5:$I$304,$D$5:$D$304,$K7,$B$5:$B$304,6,$C$5:$C$304,Parametros!$B$4)) -> 0 | R7: =IF($K7="","",SUMIFS($I$5:$I$304,$D$5:$D$304,$K7,$B$5:$B$304,7,$C$5:$C$304,Parametros!$B$4)) -> 0 | S7: =IF($K7="","",SUMIFS($I$5:$I$304,$D$5:$D$304,$K7,$B$5:$B$304,8,$C$5:$C$304,Parametros!$B$4)) -> 0 | T7: =IF($K7="","",SUMIFS($I$5:$I$304,$D$5:$D$304,$K7,$B$5:$B$304,9,$C$5:$C$304,Parametros!$B$4)) -> 0 | U7: =IF($K7="","",SUMIFS($I$5:$I$304,$D$5:$D$304,$K7,$B$5:$B$304,10,$C$5:$C$304,Parametros!$B$4)) -> 167.5 | V7: =IF($K7="","",SUMIFS($I$5:$I$304,$D$5:$D$304,$K7,$B$5:$B$304,11,$C$5:$C$304,Parametros!$B$4)) -> 0 | W7: =IF($K7="","",SUMIFS($I$5:$I$304,$D$5:$D$304,$K7,$B$5:$B$304,12,$C$5:$C$304,Parametros!$B$4)) -> 0 | X7: =IF($K7="","",SUM(L7:W7)) -> 167.5
B8: =IF(A8="","",MONTH(A8)) | C8: =IF(A8="","",YEAR(A8)) | I8: =IF(G8="","",G8*H8) | K8: =IF(Parametros!$A$10="","",Parametros!$A$10) -> Chiclayo | L8: =IF($K8="","",SUMIFS($I$5:$I$304,$D$5:$D$304,$K8,$B$5:$B$304,1,$C$5:$C$304,Parametros!$B$4)) -> 0 | M8: =IF($K8="","",SUMIFS($I$5:$I$304,$D$5:$D$304,$K8,$B$5:$B$304,2,$C$5:$C$304,Parametros!$B$4)) -> 0 | N8: =IF($K8="","",SUMIFS($I$5:$I$304,$D$5:$D$304,$K8,$B$5:$B$304,3,$C$5:$C$304,Parametros!$B$4)) -> 0 | O8: =IF($K8="","",SUMIFS($I$5:$I$304,$D$5:$D$304,$K8,$B$5:$B$304,4,$C$5:$C$304,Parametros!$B$4)) -> 0 | P8: =IF($K8="","",SUMIFS($I$5:$I$304,$D$5:$D$304,$K8,$B$5:$B$304,5,$C$5:$C$304,Parametros!$B$4)) -> 0 | Q8: =IF($K8="","",SUMIFS($I$5:$I$304,$D$5:$D$304,$K8,$B$5:$B$304,6,$C$5:$C$304,Parametros!$B$4)) -> 0 | R8: =IF($K8="","",SUMIFS($I$5:$I$304,$D$5:$D$304,$K8,$B$5:$B$304,7,$C$5:$C$304,Parametros!$B$4)) -> 0 | S8: =IF($K8="","",SUMIFS($I$5:$I$304,$D$5:$D$304,$K8,$B$5:$B$304,8,$C$5:$C$304,Parametros!$B$4)) -> 0 | T8: =IF($K8="","",SUMIFS($I$5:$I$304,$D$5:$D$304,$K8,$B$5:$B$304,9,$C$5:$C$304,Parametros!$B$4)) -> 0 | U8: =IF($K8="","",SUMIFS($I$5:$I$304,$D$5:$D$304,$K8,$B$5:$B$304,10,$C$5:$C$304,Parametros!$B$4)) -> 0 | V8: =IF($K8="","",SUMIFS($I$5:$I$304,$D$5:$D$304,$K8,$B$5:$B$304,11,$C$5:$C$304,Parametros!$B$4)) -> 0 | W8: =IF($K8="","",SUMIFS($I$5:$I$304,$D$5:$D$304,$K8,$B$5:$B$304,12,$C$5:$C$304,Parametros!$B$4)) -> 0 | X8: =IF($K8="","",SUM(L8:W8)) -> 0
B9: =IF(A9="","",MONTH(A9)) | C9: =IF(A9="","",YEAR(A9)) | I9: =IF(G9="","",G9*H9) | K9: =IF(Parametros!$A$11="","",Parametros!$A$11) -> Piura | L9: =IF($K9="","",SUMIFS($I$5:$I$304,$D$5:$D$304,$K9,$B$5:$B$304,1,$C$5:$C$304,Parametros!$B$4)) -> 0 | M9: =IF($K9="","",SUMIFS($I$5:$I$304,$D$5:$D$304,$K9,$B$5:$B$304,2,$C$5:$C$304,Parametros!$B$4)) -> 0 | N9: =IF($K9="","",SUMIFS($I$5:$I$304,$D$5:$D$304,$K9,$B$5:$B$304,3,$C$5:$C$304,Parametros!$B$4)) -> 0 | O9: =IF($K9="","",SUMIFS($I$5:$I$304,$D$5:$D$304,$K9,$B$5:$B$304,4,$C$5:$C$304,Parametros!$B$4)) -> 0 | P9: =IF($K9="","",SUMIFS($I$5:$I$304,$D$5:$D$304,$K9,$B$5:$B$304,5,$C$5:$C$304,Parametros!$B$4)) -> 0 | Q9: =IF($K9="","",SUMIFS($I$5:$I$304,$D$5:$D$304,$K9,$B$5:$B$304,6,$C$5:$C$304,Parametros!$B$4)) -> 0 | R9: =IF($K9="","",SUMIFS($I$5:$I$304,$D$5:$D$304,$K9,$B$5:$B$304,7,$C$5:$C$304,Parametros!$B$4)) -> 0 | S9: =IF($K9="","",SUMIFS($I$5:$I$304,$D$5:$D$304,$K9,$B$5:$B$304,8,$C$5:$C$304,Parametros!$B$4)) -> 0 | T9: =IF($K9="","",SUMIFS($I$5:$I$304,$D$5:$D$304,$K9,$B$5:$B$304,9,$C$5:$C$304,Parametros!$B$4)) -> 0 | U9: =IF($K9="","",SUMIFS($I$5:$I$304,$D$5:$D$304,$K9,$B$5:$B$304,10,$C$5:$C$304,Parametros!$B$4)) -> 0 | V9: =IF($K9="","",SUMIFS($I$5:$I$304,$D$5:$D$304,$K9,$B$5:$B$304,11,$C$5:$C$304,Parametros!$B$4)) -> 0 | W9: =IF($K9="","",SUMIFS($I$5:$I$304,$D$5:$D$304,$K9,$B$5:$B$304,12,$C$5:$C$304,Parametros!$B$4)) -> 0 | X9: =IF($K9="","",SUM(L9:W9)) -> 0
B10: =IF(A10="","",MONTH(A10)) | C10: =IF(A10="","",YEAR(A10)) | I10: =IF(G10="","",G10*H10) | K10: =IF(Parametros!$A$12="","",Parametros!$A$12) | L10: =IF($K10="","",SUMIFS($I$5:$I$304,$D$5:$D$304,$K10,$B$5:$B$304,1,$C$5:$C$304,Parametros!$B$4)) | M10: =IF($K10="","",SUMIFS($I$5:$I$304,$D$5:$D$304,$K10,$B$5:$B$304,2,$C$5:$C$304,Parametros!$B$4)) | N10: =IF($K10="","",SUMIFS($I$5:$I$304,$D$5:$D$304,$K10,$B$5:$B$304,3,$C$5:$C$304,Parametros!$B$4)) | O10: =IF($K10="","",SUMIFS($I$5:$I$304,$D$5:$D$304,$K10,$B$5:$B$304,4,$C$5:$C$304,Parametros!$B$4)) | P10: =IF($K10="","",SUMIFS($I$5:$I$304,$D$5:$D$304,$K10,$B$5:$B$304,5,$C$5:$C$304,Parametros!$B$4)) | Q10: =IF($K10="","",SUMIFS($I$5:$I$304,$D$5:$D$304,$K10,$B$5:$B$304,6,$C$5:$C$304,Parametros!$B$4)) | R10: =IF($K10="","",SUMIFS($I$5:$I$304,$D$5:$D$304,$K10,$B$5:$B$304,7,$C$5:$C$304,Parametros!$B$4)) | S10: =IF($K10="","",SUMIFS($I$5:$I$304,$D$5:$D$304,$K10,$B$5:$B$304,8,$C$5:$C$304,Parametros!$B$4)) | T10: =IF($K10="","",SUMIFS($I$5:$I$304,$D$5:$D$304,$K10,$B$5:$B$304,9,$C$5:$C$304,Parametros!$B$4)) | U10: =IF($K10="","",SUMIFS($I$5:$I$304,$D$5:$D$304,$K10,$B$5:$B$304,10,$C$5:$C$304,Parametros!$B$4)) | V10: =IF($K10="","",SUMIFS($I$5:$I$304,$D$5:$D$304,$K10,$B$5:$B$304,11,$C$5:$C$304,Parametros!$B$4)) | W10: =IF($K10="","",SUMIFS($I$5:$I$304,$D$5:$D$304,$K10,$B$5:$B$304,12,$C$5:$C$304,Parametros!$B$4)) | X10: =IF($K10="","",SUM(L10:W10))
B11: =IF(A11="","",MONTH(A11)) | C11: =IF(A11="","",YEAR(A11)) | I11: =IF(G11="","",G11*H11) | K11: =IF(Parametros!$A$13="","",Parametros!$A$13) | L11: =IF($K11="","",SUMIFS($I$5:$I$304,$D$5:$D$304,$K11,$B$5:$B$304,1,$C$5:$C$304,Parametros!$B$4)) | M11: =IF($K11="","",SUMIFS($I$5:$I$304,$D$5:$D$304,$K11,$B$5:$B$304,2,$C$5:$C$304,Parametros!$B$4)) | N11: =IF($K11="","",SUMIFS($I$5:$I$304,$D$5:$D$304,$K11,$B$5:$B$304,3,$C$5:$C$304,Parametros!$B$4)) | O11: =IF($K11="","",SUMIFS($I$5:$I$304,$D$5:$D$304,$K11,$B$5:$B$304,4,$C$5:$C$304,Parametros!$B$4)) | P11: =IF($K11="","",SUMIFS($I$5:$I$304,$D$5:$D$304,$K11,$B$5:$B$304,5,$C$5:$C$304,Parametros!$B$4)) | Q11: =IF($K11="","",SUMIFS($I$5:$I$304,$D$5:$D$304,$K11,$B$5:$B$304,6,$C$5:$C$304,Parametros!$B$4)) | R11: =IF($K11="","",SUMIFS($I$5:$I$304,$D$5:$D$304,$K11,$B$5:$B$304,7,$C$5:$C$304,Parametros!$B$4)) | S11: =IF($K11="","",SUMIFS($I$5:$I$304,$D$5:$D$304,$K11,$B$5:$B$304,8,$C$5:$C$304,Parametros!$B$4)) | T11: =IF($K11="","",SUMIFS($I$5:$I$304,$D$5:$D$304,$K11,$B$5:$B$304,9,$C$5:$C$304,Parametros!$B$4)) | U11: =IF($K11="","",SUMIFS($I$5:$I$304,$D$5:$D$304,$K11,$B$5:$B$304,10,$C$5:$C$304,Parametros!$B$4)) | V11: =IF($K11="","",SUMIFS($I$5:$I$304,$D$5:$D$304,$K11,$B$5:$B$304,11,$C$5:$C$304,Parametros!$B$4)) | W11: =IF($K11="","",SUMIFS($I$5:$I$304,$D$5:$D$304,$K11,$B$5:$B$304,12,$C$5:$C$304,Parametros!$B$4)) | X11: =IF($K11="","",SUM(L11:W11))
B12: =IF(A12="","",MONTH(A12)) | C12: =IF(A12="","",YEAR(A12)) | I12: =IF(G12="","",G12*H12) | K12: =IF(Parametros!$A$14="","",Parametros!$A$14) | L12: =IF($K12="","",SUMIFS($I$5:$I$304,$D$5:$D$304,$K12,$B$5:$B$304,1,$C$5:$C$304,Parametros!$B$4)) | M12: =IF($K12="","",SUMIFS($I$5:$I$304,$D$5:$D$304,$K12,$B$5:$B$304,2,$C$5:$C$304,Parametros!$B$4)) | N12: =IF($K12="","",SUMIFS($I$5:$I$304,$D$5:$D$304,$K12,$B$5:$B$304,3,$C$5:$C$304,Parametros!$B$4)) | O12: =IF($K12="","",SUMIFS($I$5:$I$304,$D$5:$D$304,$K12,$B$5:$B$304,4,$C$5:$C$304,Parametros!$B$4)) | P12: =IF($K12="","",SUMIFS($I$5:$I$304,$D$5:$D$304,$K12,$B$5:$B$304,5,$C$5:$C$304,Parametros!$B$4)) | Q12: =IF($K12="","",SUMIFS($I$5:$I$304,$D$5:$D$304,$K12,$B$5:$B$304,6,$C$5:$C$304,Parametros!$B$4)) | R12: =IF($K12="","",SUMIFS($I$5:$I$304,$D$5:$D$304,$K12,$B$5:$B$304,7,$C$5:$C$304,Parametros!$B$4)) | S12: =IF($K12="","",SUMIFS($I$5:$I$304,$D$5:$D$304,$K12,$B$5:$B$304,8,$C$5:$C$304,Parametros!$B$4)) | T12: =IF($K12="","",SUMIFS($I$5:$I$304,$D$5:$D$304,$K12,$B$5:$B$304,9,$C$5:$C$304,Parametros!$B$4)) | U12: =IF($K12="","",SUMIFS($I$5:$I$304,$D$5:$D$304,$K12,$B$5:$B$304,10,$C$5:$C$304,Parametros!$B$4)) | V12: =IF($K12="","",SUMIFS($I$5:$I$304,$D$5:$D$304,$K12,$B$5:$B$304,11,$C$5:$C$304,Parametros!$B$4)) | W12: =IF($K12="","",SUMIFS($I$5:$I$304,$D$5:$D$304,$K12,$B$5:$B$304,12,$C$5:$C$304,Parametros!$B$4)) | X12: =IF($K12="","",SUM(L12:W12))
B13: =IF(A13="","",MONTH(A13)) | C13: =IF(A13="","",YEAR(A13)) | I13: =IF(G13="","",G13*H13) | K13: =IF(Parametros!$A$15="","",Parametros!$A$15) | L13: =IF($K13="","",SUMIFS($I$5:$I$304,$D$5:$D$304,$K13,$B$5:$B$304,1,$C$5:$C$304,Parametros!$B$4)) | M13: =IF($K13="","",SUMIFS($I$5:$I$304,$D$5:$D$304,$K13,$B$5:$B$304,2,$C$5:$C$304,Parametros!$B$4)) | N13: =IF($K13="","",SUMIFS($I$5:$I$304,$D$5:$D$304,$K13,$B$5:$B$304,3,$C$5:$C$304,Parametros!$B$4)) | O13: =IF($K13="","",SUMIFS($I$5:$I$304,$D$5:$D$304,$K13,$B$5:$B$304,4,$C$5:$C$304,Parametros!$B$4)) | P13: =IF($K13="","",SUMIFS($I$5:$I$304,$D$5:$D$304,$K13,$B$5:$B$304,5,$C$5:$C$304,Parametros!$B$4)) | Q13: =IF($K13="","",SUMIFS($I$5:$I$304,$D$5:$D$304,$K13,$B$5:$B$304,6,$C$5:$C$304,Parametros!$B$4)) | R13: =IF($K13="","",SUMIFS($I$5:$I$304,$D$5:$D$304,$K13,$B$5:$B$304,7,$C$5:$C$304,Parametros!$B$4)) | S13: =IF($K13="","",SUMIFS($I$5:$I$304,$D$5:$D$304,$K13,$B$5:$B$304,8,$C$5:$C$304,Parametros!$B$4)) | T13: =IF($K13="","",SUMIFS($I$5:$I$304,$D$5:$D$304,$K13,$B$5:$B$304,9,$C$5:$C$304,Parametros!$B$4)) | U13: =IF($K13="","",SUMIFS($I$5:$I$304,$D$5:$D$304,$K13,$B$5:$B$304,10,$C$5:$C$304,Parametros!$B$4)) | V13: =IF($K13="","",SUMIFS($I$5:$I$304,$D$5:$D$304,$K13,$B$5:$B$304,11,$C$5:$C$304,Parametros!$B$4)) | W13: =IF($K13="","",SUMIFS($I$5:$I$304,$D$5:$D$304,$K13,$B$5:$B$304,12,$C$5:$C$304,Parametros!$B$4)) | X13: =IF($K13="","",SUM(L13:W13))
B14: =IF(A14="","",MONTH(A14)) | C14: =IF(A14="","",YEAR(A14)) | I14: =IF(G14="","",G14*H14) | K14: =IF(Parametros!$A$16="","",Parametros!$A$16) | L14: =IF($K14="","",SUMIFS($I$5:$I$304,$D$5:$D$304,$K14,$B$5:$B$304,1,$C$5:$C$304,Parametros!$B$4)) | M14: =IF($K14="","",SUMIFS($I$5:$I$304,$D$5:$D$304,$K14,$B$5:$B$304,2,$C$5:$C$304,Parametros!$B$4)) | N14: =IF($K14="","",SUMIFS($I$5:$I$304,$D$5:$D$304,$K14,$B$5:$B$304,3,$C$5:$C$304,Parametros!$B$4)) | O14: =IF($K14="","",SUMIFS($I$5:$I$304,$D$5:$D$304,$K14,$B$5:$B$304,4,$C$5:$C$304,Parametros!$B$4)) | P14: =IF($K14="","",SUMIFS($I$5:$I$304,$D$5:$D$304,$K14,$B$5:$B$304,5,$C$5:$C$304,Parametros!$B$4)) | Q14: =IF($K14="","",SUMIFS($I$5:$I$304,$D$5:$D$304,$K14,$B$5:$B$304,6,$C$5:$C$304,Parametros!$B$4)) | R14: =IF($K14="","",SUMIFS($I$5:$I$304,$D$5:$D$304,$K14,$B$5:$B$304,7,$C$5:$C$304,Parametros!$B$4)) | S14: =IF($K14="","",SUMIFS($I$5:$I$304,$D$5:$D$304,$K14,$B$5:$B$304,8,$C$5:$C$304,Parametros!$B$4)) | T14: =IF($K14="","",SUMIFS($I$5:$I$304,$D$5:$D$304,$K14,$B$5:$B$304,9,$C$5:$C$304,Parametros!$B$4)) | U14: =IF($K14="","",SUMIFS($I$5:$I$304,$D$5:$D$304,$K14,$B$5:$B$304,10,$C$5:$C$304,Parametros!$B$4)) | V14: =IF($K14="","",SUMIFS($I$5:$I$304,$D$5:$D$304,$K14,$B$5:$B$304,11,$C$5:$C$304,Parametros!$B$4)) | W14: =IF($K14="","",SUMIFS($I$5:$I$304,$D$5:$D$304,$K14,$B$5:$B$304,12,$C$5:$C$304,Parametros!$B$4)) | X14: =IF($K14="","",SUM(L14:W14))
B15: =IF(A15="","",MONTH(A15)) | C15: =IF(A15="","",YEAR(A15)) | I15: =IF(G15="","",G15*H15) | K15: TOTAL | L15: =SUM(L5:L14) -> 0 | M15: =SUM(M5:M14) -> 0 | N15: =SUM(N5:N14) -> 0 | O15: =SUM(O5:O14) -> 0 | P15: =SUM(P5:P14) -> 0 | Q15: =SUM(Q5:Q14) -> 0 | R15: =SUM(R5:R14) -> 0 | S15: =SUM(S5:S14) -> 0 | ... X15: =SUM(X5:X14) -> 1107.5
B16: =IF(A16="","",MONTH(A16)) | C16: =IF(A16="","",YEAR(A16)) | I16: =IF(G16="","",G16*H16)
B17: =IF(A17="","",MONTH(A17)) | C17: =IF(A17="","",YEAR(A17)) | I17: =IF(G17="","",G17*H17)
B18: =IF(A18="","",MONTH(A18)) | C18: =IF(A18="","",YEAR(A18)) | I18: =IF(G18="","",G18*H18)
B19: =IF(A19="","",MONTH(A19)) | C19: =IF(A19="","",YEAR(A19)) | I19: =IF(G19="","",G19*H19)
B20: =IF(A20="","",MONTH(A20)) | C20: =IF(A20="","",YEAR(A20)) | I20: =IF(G20="","",G20*H20)
B21: =IF(A21="","",MONTH(A21)) | C21: =IF(A21="","",YEAR(A21)) | I21: =IF(G21="","",G21*H21)
B22: =IF(A22="","",MONTH(A22)) | C22: =IF(A22="","",YEAR(A22)) | I22: =IF(G22="","",G22*H22)
B23: =IF(A23="","",MONTH(A23)) | C23: =IF(A23="","",YEAR(A23)) | I23: =IF(G23="","",G23*H23)
B24: =IF(A24="","",MONTH(A24)) | C24: =IF(A24="","",YEAR(A24)) | I24: =IF(G24="","",G24*H24)
B25: =IF(A25="","",MONTH(A25)) | C25: =IF(A25="","",YEAR(A25)) | I25: =IF(G25="","",G25*H25)
B26: =IF(A26="","",MONTH(A26)) | C26: =IF(A26="","",YEAR(A26)) | I26: =IF(G26="","",G26*H26)
B27: =IF(A27="","",MONTH(A27)) | C27: =IF(A27="","",YEAR(A27)) | I27: =IF(G27="","",G27*H27)
... B304: =IF(A304="","",MONTH(A304)) | C304: =IF(A304="","",YEAR(A304)) | I304: =IF(G304="","",G304*H304)

Sheet Reportes
A1: Reportes de compras
A2: Todo es automático, calculado del año en Parametros!B4.
A3: ="Año de análisis: "&Parametros!B4 -> Año de análisis: 2026
A5: Mes | B5: Compras total (S/) | C5: Crédito (S/) | D5: Contado (S/) | E5: % Crédito | F5: % Contado | G5: N° OC | H5: Ahorro negociación (S/) | I5: Sesiones | J5: Costo insumos (S/) | K5: Costo prom. por sesión (S/) | L5: Consumo total (S/)
A6: Ene | B6: =SUMIFS(Seguimiento_OC!$G$5:$G$304,Seguimiento_OC!$B$5:$B$304,">="&DATE(Parametros!$B$4,1,1),Seguimiento_OC!$B$5:$B$304,"<"&DATE(Parametros!$B$4,1+1,1)) -> 0 | C6: =SUMIFS(Seguimiento_OC!$G$5:$G$304,Seguimiento_OC!$F$5:$F$304,"Crédito",Seguimiento_OC!$B$5:$B$304,">="&DATE(Parametros!$B$4,1,1),Seguimiento_OC!$B$5:$B$304,"<"&DATE(Parametros!$B$4,1+1,1)) -> 0 | D6: =SUMIFS(Seguimiento_OC!$G$5:$G$304,Seguimiento_OC!$F$5:$F$304,"Contado",Seguimiento_OC!$B$5:$B$304,">="&DATE(Parametros!$B$4,1,1),Seguimiento_OC!$B$5:$B$304,"<"&DATE(Parametros!$B$4,1+1,1)) -> 0 | E6: =IF(B6=0,0,C6/B6) -> 0 | F6: =IF(B6=0,0,D6/B6) -> 0 | G6: =COUNTIFS(Seguimiento_OC!$B$5:$B$304,">="&DATE(Parametros!$B$4,1,1),Seguimiento_OC!$B$5:$B$304,"<"&DATE(Parametros!$B$4,1+1,1)) -> 0 | H6: =SUMIFS(Comparativo!$S$5:$S$304,Comparativo!$B$5:$B$304,">="&DATE(Parametros!$B$4,1,1),Comparativo!$B$5:$B$304,"<"&DATE(Parametros!$B$4,1+1,1)) -> 0 | I6: =SUMIFS(Produccion!$E$5:$E$304,Produccion!$A$5:$A$304,Parametros!$B$4,Produccion!$B$5:$B$304,1) -> 0 | J6: =SUMIFS(Produccion!$F$5:$F$304,Produccion!$A$5:$A$304,Parametros!$B$4,Produccion!$B$5:$B$304,1) -> 0 | K6: =IF(I6=0,0,J6/I6) -> 0 | L6: =Consumos!L15 -> 0
A7: Feb | B7: =SUMIFS(Seguimiento_OC!$G$5:$G$304,Seguimiento_OC!$B$5:$B$304,">="&DATE(Parametros!$B$4,2,1),Seguimiento_OC!$B$5:$B$304,"<"&DATE(Parametros!$B$4,2+1,1)) -> 0 | C7: =SUMIFS(Seguimiento_OC!$G$5:$G$304,Seguimiento_OC!$F$5:$F$304,"Crédito",Seguimiento_OC!$B$5:$B$304,">="&DATE(Parametros!$B$4,2,1),Seguimiento_OC!$B$5:$B$304,"<"&DATE(Parametros!$B$4,2+1,1)) -> 0 | D7: =SUMIFS(Seguimiento_OC!$G$5:$G$304,Seguimiento_OC!$F$5:$F$304,"Contado",Seguimiento_OC!$B$5:$B$304,">="&DATE(Parametros!$B$4,2,1),Seguimiento_OC!$B$5:$B$304,"<"&DATE(Parametros!$B$4,2+1,1)) -> 0 | E7: =IF(B7=0,0,C7/B7) -> 0 | F7: =IF(B7=0,0,D7/B7) -> 0 | G7: =COUNTIFS(Seguimiento_OC!$B$5:$B$304,">="&DATE(Parametros!$B$4,2,1),Seguimiento_OC!$B$5:$B$304,"<"&DATE(Parametros!$B$4,2+1,1)) -> 0 | H7: =SUMIFS(Comparativo!$S$5:$S$304,Comparativo!$B$5:$B$304,">="&DATE(Parametros!$B$4,2,1),Comparativo!$B$5:$B$304,"<"&DATE(Parametros!$B$4,2+1,1)) -> 0 | I7: =SUMIFS(Produccion!$E$5:$E$304,Produccion!$A$5:$A$304,Parametros!$B$4,Produccion!$B$5:$B$304,2) -> 0 | J7: =SUMIFS(Produccion!$F$5:$F$304,Produccion!$A$5:$A$304,Parametros!$B$4,Produccion!$B$5:$B$304,2) -> 0 | K7: =IF(I7=0,0,J7/I7) -> 0 | L7: =Consumos!M15 -> 0
A8: Mar | B8: =SUMIFS(Seguimiento_OC!$G$5:$G$304,Seguimiento_OC!$B$5:$B$304,">="&DATE(Parametros!$B$4,3,1),Seguimiento_OC!$B$5:$B$304,"<"&DATE(Parametros!$B$4,3+1,1)) -> 0 | C8: =SUMIFS(Seguimiento_OC!$G$5:$G$304,Seguimiento_OC!$F$5:$F$304,"Crédito",Seguimiento_OC!$B$5:$B$304,">="&DATE(Parametros!$B$4,3,1),Seguimiento_OC!$B$5:$B$304,"<"&DATE(Parametros!$B$4,3+1,1)) -> 0 | D8: =SUMIFS(Seguimiento_OC!$G$5:$G$304,Seguimiento_OC!$F$5:$F$304,"Contado",Seguimiento_OC!$B$5:$B$304,">="&DATE(Parametros!$B$4,3,1),Seguimiento_OC!$B$5:$B$304,"<"&DATE(Parametros!$B$4,3+1,1)) -> 0 | E8: =IF(B8=0,0,C8/B8) -> 0 | F8: =IF(B8=0,0,D8/B8) -> 0 | G8: =COUNTIFS(Seguimiento_OC!$B$5:$B$304,">="&DATE(Parametros!$B$4,3,1),Seguimiento_OC!$B$5:$B$304,"<"&DATE(Parametros!$B$4,3+1,1)) -> 0 | H8: =SUMIFS(Comparativo!$S$5:$S$304,Comparativo!$B$5:$B$304,">="&DATE(Parametros!$B$4,3,1),Comparativo!$B$5:$B$304,"<"&DATE(Parametros!$B$4,3+1,1)) -> 0 | I8: =SUMIFS(Produccion!$E$5:$E$304,Produccion!$A$5:$A$304,Parametros!$B$4,Produccion!$B$5:$B$304,3) -> 0 | J8: =SUMIFS(Produccion!$F$5:$F$304,Produccion!$A$5:$A$304,Parametros!$B$4,Produccion!$B$5:$B$304,3) -> 0 | K8: =IF(I8=0,0,J8/I8) -> 0 | L8: =Consumos!N15 -> 0
A9: Abr | B9: =SUMIFS(Seguimiento_OC!$G$5:$G$304,Seguimiento_OC!$B$5:$B$304,">="&DATE(Parametros!$B$4,4,1),Seguimiento_OC!$B$5:$B$304,"<"&DATE(Parametros!$B$4,4+1,1)) -> 0 | C9: =SUMIFS(Seguimiento_OC!$G$5:$G$304,Seguimiento_OC!$F$5:$F$304,"Crédito",Seguimiento_OC!$B$5:$B$304,">="&DATE(Parametros!$B$4,4,1),Seguimiento_OC!$B$5:$B$304,"<"&DATE(Parametros!$B$4,4+1,1)) -> 0 | D9: =SUMIFS(Seguimiento_OC!$G$5:$G$304,Seguimiento_OC!$F$5:$F$304,"Contado",Seguimiento_OC!$B$5:$B$304,">="&DATE(Parametros!$B$4,4,1),Seguimiento_OC!$B$5:$B$304,"<"&DATE(Parametros!$B$4,4+1,1)) -> 0 | E9: =IF(B9=0,0,C9/B9) -> 0 | F9: =IF(B9=0,0,D9/B9) -> 0 | G9: =COUNTIFS(Seguimiento_OC!$B$5:$B$304,">="&DATE(Parametros!$B$4,4,1),Seguimiento_OC!$B$5:$B$304,"<"&DATE(Parametros!$B$4,4+1,1)) -> 0 | H9: =SUMIFS(Comparativo!$S$5:$S$304,Comparativo!$B$5:$B$304,">="&DATE(Parametros!$B$4,4,1),Comparativo!$B$5:$B$304,"<"&DATE(Parametros!$B$4,4+1,1)) -> 0 | I9: =SUMIFS(Produccion!$E$5:$E$304,Produccion!$A$5:$A$304,Parametros!$B$4,Produccion!$B$5:$B$304,4) -> 0 | J9: =SUMIFS(Produccion!$F$5:$F$304,Produccion!$A$5:$A$304,Parametros!$B$4,Produccion!$B$5:$B$304,4) -> 0 | K9: =IF(I9=0,0,J9/I9) -> 0 | L9: =Consumos!O15 -> 0
A10: May | B10: =SUMIFS(Seguimiento_OC!$G$5:$G$304,Seguimiento_OC!$B$5:$B$304,">="&DATE(Parametros!$B$4,5,1),Seguimiento_OC!$B$5:$B$304,"<"&DATE(Parametros!$B$4,5+1,1)) -> 0 | C10: =SUMIFS(Seguimiento_OC!$G$5:$G$304,Seguimiento_OC!$F$5:$F$304,"Crédito",Seguimiento_OC!$B$5:$B$304,">="&DATE(Parametros!$B$4,5,1),Seguimiento_OC!$B$5:$B$304,"<"&DATE(Parametros!$B$4,5+1,1)) -> 0 | D10: =SUMIFS(Seguimiento_OC!$G$5:$G$304,Seguimiento_OC!$F$5:$F$304,"Contado",Seguimiento_OC!$B$5:$B$304,">="&DATE(Parametros!$B$4,5,1),Seguimiento_OC!$B$5:$B$304,"<"&DATE(Parametros!$B$4,5+1,1)) -> 0 | E10: =IF(B10=0,0,C10/B10) -> 0 | F10: =IF(B10=0,0,D10/B10) -> 0 | G10: =COUNTIFS(Seguimiento_OC!$B$5:$B$304,">="&DATE(Parametros!$B$4,5,1),Seguimiento_OC!$B$5:$B$304,"<"&DATE(Parametros!$B$4,5+1,1)) -> 0 | H10: =SUMIFS(Comparativo!$S$5:$S$304,Comparativo!$B$5:$B$304,">="&DATE(Parametros!$B$4,5,1),Comparativo!$B$5:$B$304,"<"&DATE(Parametros!$B$4,5+1,1)) -> 0 | I10: =SUMIFS(Produccion!$E$5:$E$304,Produccion!$A$5:$A$304,Parametros!$B$4,Produccion!$B$5:$B$304,5) -> 0 | J10: =SUMIFS(Produccion!$F$5:$F$304,Produccion!$A$5:$A$304,Parametros!$B$4,Produccion!$B$5:$B$304,5) -> 0 | K10: =IF(I10=0,0,J10/I10) -> 0 | L10: =Consumos!P15 -> 0
A11: Jun | B11: =SUMIFS(Seguimiento_OC!$G$5:$G$304,Seguimiento_OC!$B$5:$B$304,">="&DATE(Parametros!$B$4,6,1),Seguimiento_OC!$B$5:$B$304,"<"&DATE(Parametros!$B$4,6+1,1)) -> 0 | C11: =SUMIFS(Seguimiento_OC!$G$5:$G$304,Seguimiento_OC!$F$5:$F$304,"Crédito",Seguimiento_OC!$B$5:$B$304,">="&DATE(Parametros!$B$4,6,1),Seguimiento_OC!$B$5:$B$304,"<"&DATE(Parametros!$B$4,6+1,1)) -> 0 | D11: =SUMIFS(Seguimiento_OC!$G$5:$G$304,Seguimiento_OC!$F$5:$F$304,"Contado",Seguimiento_OC!$B$5:$B$304,">="&DATE(Parametros!$B$4,6,1),Seguimiento_OC!$B$5:$B$304,"<"&DATE(Parametros!$B$4,6+1,1)) -> 0 | E11: =IF(B11=0,0,C11/B11) -> 0 | F11: =IF(B11=0,0,D11/B11) -> 0 | G11: =COUNTIFS(Seguimiento_OC!$B$5:$B$304,">="&DATE(Parametros!$B$4,6,1),Seguimiento_OC!$B$5:$B$304,"<"&DATE(Parametros!$B$4,6+1,1)) -> 0 | H11: =SUMIFS(Comparativo!$S$5:$S$304,Comparativo!$B$5:$B$304,">="&DATE(Parametros!$B$4,6,1),Comparativo!$B$5:$B$304,"<"&DATE(Parametros!$B$4,6+1,1)) -> 0 | I11: =SUMIFS(Produccion!$E$5:$E$304,Produccion!$A$5:$A$304,Parametros!$B$4,Produccion!$B$5:$B$304,6) -> 0 | J11: =SUMIFS(Produccion!$F$5:$F$304,Produccion!$A$5:$A$304,Parametros!$B$4,Produccion!$B$5:$B$304,6) -> 0 | K11: =IF(I11=0,0,J11/I11) -> 0 | L11: =Consumos!Q15 -> 0
A12: Jul | B12: =SUMIFS(Seguimiento_OC!$G$5:$G$304,Seguimiento_OC!$B$5:$B$304,">="&DATE(Parametros!$B$4,7,1),Seguimiento_OC!$B$5:$B$304,"<"&DATE(Parametros!$B$4,7+1,1)) -> 0 | C12: =SUMIFS(Seguimiento_OC!$G$5:$G$304,Seguimiento_OC!$F$5:$F$304,"Crédito",Seguimiento_OC!$B$5:$B$304,">="&DATE(Parametros!$B$4,7,1),Seguimiento_OC!$B$5:$B$304,"<"&DATE(Parametros!$B$4,7+1,1)) -> 0 | D12: =SUMIFS(Seguimiento_OC!$G$5:$G$304,Seguimiento_OC!$F$5:$F$304,"Contado",Seguimiento_OC!$B$5:$B$304,">="&DATE(Parametros!$B$4,7,1),Seguimiento_OC!$B$5:$B$304,"<"&DATE(Parametros!$B$4,7+1,1)) -> 0 | E12: =IF(B12=0,0,C12/B12) -> 0 | F12: =IF(B12=0,0,D12/B12) -> 0 | G12: =COUNTIFS(Seguimiento_OC!$B$5:$B$304,">="&DATE(Parametros!$B$4,7,1),Seguimiento_OC!$B$5:$B$304,"<"&DATE(Parametros!$B$4,7+1,1)) -> 0 | H12: =SUMIFS(Comparativo!$S$5:$S$304,Comparativo!$B$5:$B$304,">="&DATE(Parametros!$B$4,7,1),Comparativo!$B$5:$B$304,"<"&DATE(Parametros!$B$4,7+1,1)) -> 0 | I12: =SUMIFS(Produccion!$E$5:$E$304,Produccion!$A$5:$A$304,Parametros!$B$4,Produccion!$B$5:$B$304,7) -> 0 | J12: =SUMIFS(Produccion!$F$5:$F$304,Produccion!$A$5:$A$304,Parametros!$B$4,Produccion!$B$5:$B$304,7) -> 0 | K12: =IF(I12=0,0,J12/I12) -> 0 | L12: =Consumos!R15 -> 0
A13: Ago | B13: =SUMIFS(Seguimiento_OC!$G$5:$G$304,Seguimiento_OC!$B$5:$B$304,">="&DATE(Parametros!$B$4,8,1),Seguimiento_OC!$B$5:$B$304,"<"&DATE(Parametros!$B$4,8+1,1)) -> 0 | C13: =SUMIFS(Seguimiento_OC!$G$5:$G$304,Seguimiento_OC!$F$5:$F$304,"Crédito",Seguimiento_OC!$B$5:$B$304,">="&DATE(Parametros!$B$4,8,1),Seguimiento_OC!$B$5:$B$304,"<"&DATE(Parametros!$B$4,8+1,1)) -> 0 | D13: =SUMIFS(Seguimiento_OC!$G$5:$G$304,Seguimiento_OC!$F$5:$F$304,"Contado",Seguimiento_OC!$B$5:$B$304,">="&DATE(Parametros!$B$4,8,1),Seguimiento_OC!$B$5:$B$304,"<"&DATE(Parametros!$B$4,8+1,1)) -> 0 | E13: =IF(B13=0,0,C13/B13) -> 0 | F13: =IF(B13=0,0,D13/B13) -> 0 | G13: =COUNTIFS(Seguimiento_OC!$B$5:$B$304,">="&DATE(Parametros!$B$4,8,1),Seguimiento_OC!$B$5:$B$304,"<"&DATE(Parametros!$B$4,8+1,1)) -> 0 | H13: =SUMIFS(Comparativo!$S$5:$S$304,Comparativo!$B$5:$B$304,">="&DATE(Parametros!$B$4,8,1),Comparativo!$B$5:$B$304,"<"&DATE(Parametros!$B$4,8+1,1)) -> 0 | I13: =SUMIFS(Produccion!$E$5:$E$304,Produccion!$A$5:$A$304,Parametros!$B$4,Produccion!$B$5:$B$304,8) -> 0 | J13: =SUMIFS(Produccion!$F$5:$F$304,Produccion!$A$5:$A$304,Parametros!$B$4,Produccion!$B$5:$B$304,8) -> 0 | K13: =IF(I13=0,0,J13/I13) -> 0 | L13: =Consumos!S15 -> 0
A14: Set | B14: =SUMIFS(Seguimiento_OC!$G$5:$G$304,Seguimiento_OC!$B$5:$B$304,">="&DATE(Parametros!$B$4,9,1),Seguimiento_OC!$B$5:$B$304,"<"&DATE(Parametros!$B$4,9+1,1)) -> 0 | C14: =SUMIFS(Seguimiento_OC!$G$5:$G$304,Seguimiento_OC!$F$5:$F$304,"Crédito",Seguimiento_OC!$B$5:$B$304,">="&DATE(Parametros!$B$4,9,1),Seguimiento_OC!$B$5:$B$304,"<"&DATE(Parametros!$B$4,9+1,1)) -> 0 | D14: =SUMIFS(Seguimiento_OC!$G$5:$G$304,Seguimiento_OC!$F$5:$F$304,"Contado",Seguimiento_OC!$B$5:$B$304,">="&DATE(Parametros!$B$4,9,1),Seguimiento_OC!$B$5:$B$304,"<"&DATE(Parametros!$B$4,9+1,1)) -> 0 | E14: =IF(B14=0,0,C14/B14) -> 0 | F14: =IF(B14=0,0,D14/B14) -> 0 | G14: =COUNTIFS(Seguimiento_OC!$B$5:$B$304,">="&DATE(Parametros!$B$4,9,1),Seguimiento_OC!$B$5:$B$304,"<"&DATE(Parametros!$B$4,9+1,1)) -> 0 | H14: =SUMIFS(Comparativo!$S$5:$S$304,Comparativo!$B$5:$B$304,">="&DATE(Parametros!$B$4,9,1),Comparativo!$B$5:$B$304,"<"&DATE(Parametros!$B$4,9+1,1)) -> 0 | I14: =SUMIFS(Produccion!$E$5:$E$304,Produccion!$A$5:$A$304,Parametros!$B$4,Produccion!$B$5:$B$304,9) -> 2660 | J14: =SUMIFS(Produccion!$F$5:$F$304,Produccion!$A$5:$A$304,Parametros!$B$4,Produccion!$B$5:$B$304,9) -> 183300 | K14: =IF(I14=0,0,J14/I14) -> 68.909774 | L14: =Consumos!T15 -> 0
A15: Oct | B15: =SUMIFS(Seguimiento_OC!$G$5:$G$304,Seguimiento_OC!$B$5:$B$304,">="&DATE(Parametros!$B$4,10,1),Seguimiento_OC!$B$5:$B$304,"<"&DATE(Parametros!$B$4,10+1,1)) -> 9327.32 | C15: =SUMIFS(Seguimiento_OC!$G$5:$G$304,Seguimiento_OC!$F$5:$F$304,"Crédito",Seguimiento_OC!$B$5:$B$304,">="&DATE(Parametros!$B$4,10,1),Seguimiento_OC!$B$5:$B$304,"<"&DATE(Parametros!$B$4,10+1,1)) -> 4017.32 | D15: =SUMIFS(Seguimiento_OC!$G$5:$G$304,Seguimiento_OC!$F$5:$F$304,"Contado",Seguimiento_OC!$B$5:$B$304,">="&DATE(Parametros!$B$4,10,1),Seguimiento_OC!$B$5:$B$304,"<"&DATE(Parametros!$B$4,10+1,1)) -> 5310 | E15: =IF(B15=0,0,C15/B15) -> 0.43070464 | F15: =IF(B15=0,0,D15/B15) -> 0.56929536 | G15: =COUNTIFS(Seguimiento_OC!$B$5:$B$304,">="&DATE(Parametros!$B$4,10,1),Seguimiento_OC!$B$5:$B$304,"<"&DATE(Parametros!$B$4,10+1,1)) -> 3 | H15: =SUMIFS(Comparativo!$S$5:$S$304,Comparativo!$B$5:$B$304,">="&DATE(Parametros!$B$4,10,1),Comparativo!$B$5:$B$304,"<"&DATE(Parametros!$B$4,10+1,1)) -> 340 | I15: =SUMIFS(Produccion!$E$5:$E$304,Produccion!$A$5:$A$304,Parametros!$B$4,Produccion!$B$5:$B$304,10) -> 1500 | J15: =SUMIFS(Produccion!$F$5:$F$304,Produccion!$A$5:$A$304,Parametros!$B$4,Produccion!$B$5:$B$304,10) -> 100500 | K15: =IF(I15=0,0,J15/I15) -> 67 | L15: =Consumos!U15 -> 1107.5
A16: Nov | B16: =SUMIFS(Seguimiento_OC!$G$5:$G$304,Seguimiento_OC!$B$5:$B$304,">="&DATE(Parametros!$B$4,11,1),Seguimiento_OC!$B$5:$B$304,"<"&DATE(Parametros!$B$4,11+1,1)) -> 0 | C16: =SUMIFS(Seguimiento_OC!$G$5:$G$304,Seguimiento_OC!$F$5:$F$304,"Crédito",Seguimiento_OC!$B$5:$B$304,">="&DATE(Parametros!$B$4,11,1),Seguimiento_OC!$B$5:$B$304,"<"&DATE(Parametros!$B$4,11+1,1)) -> 0 | D16: =SUMIFS(Seguimiento_OC!$G$5:$G$304,Seguimiento_OC!$F$5:$F$304,"Contado",Seguimiento_OC!$B$5:$B$304,">="&DATE(Parametros!$B$4,11,1),Seguimiento_OC!$B$5:$B$304,"<"&DATE(Parametros!$B$4,11+1,1)) -> 0 | E16: =IF(B16=0,0,C16/B16) -> 0 | F16: =IF(B16=0,0,D16/B16) -> 0 | G16: =COUNTIFS(Seguimiento_OC!$B$5:$B$304,">="&DATE(Parametros!$B$4,11,1),Seguimiento_OC!$B$5:$B$304,"<"&DATE(Parametros!$B$4,11+1,1)) -> 0 | H16: =SUMIFS(Comparativo!$S$5:$S$304,Comparativo!$B$5:$B$304,">="&DATE(Parametros!$B$4,11,1),Comparativo!$B$5:$B$304,"<"&DATE(Parametros!$B$4,11+1,1)) -> 0 | I16: =SUMIFS(Produccion!$E$5:$E$304,Produccion!$A$5:$A$304,Parametros!$B$4,Produccion!$B$5:$B$304,11) -> 0 | J16: =SUMIFS(Produccion!$F$5:$F$304,Produccion!$A$5:$A$304,Parametros!$B$4,Produccion!$B$5:$B$304,11) -> 0 | K16: =IF(I16=0,0,J16/I16) -> 0 | L16: =Consumos!V15 -> 0
A17: Dic | B17: =SUMIFS(Seguimiento_OC!$G$5:$G$304,Seguimiento_OC!$B$5:$B$304,">="&DATE(Parametros!$B$4,12,1),Seguimiento_OC!$B$5:$B$304,"<"&DATE(Parametros!$B$4,12+1,1)) -> 0 | C17: =SUMIFS(Seguimiento_OC!$G$5:$G$304,Seguimiento_OC!$F$5:$F$304,"Crédito",Seguimiento_OC!$B$5:$B$304,">="&DATE(Parametros!$B$4,12,1),Seguimiento_OC!$B$5:$B$304,"<"&DATE(Parametros!$B$4,12+1,1)) -> 0 | D17: =SUMIFS(Seguimiento_OC!$G$5:$G$304,Seguimiento_OC!$F$5:$F$304,"Contado",Seguimiento_OC!$B$5:$B$304,">="&DATE(Parametros!$B$4,12,1),Seguimiento_OC!$B$5:$B$304,"<"&DATE(Parametros!$B$4,12+1,1)) -> 0 | E17: =IF(B17=0,0,C17/B17) -> 0 | F17: =IF(B17=0,0,D17/B17) -> 0 | G17: =COUNTIFS(Seguimiento_OC!$B$5:$B$304,">="&DATE(Parametros!$B$4,12,1),Seguimiento_OC!$B$5:$B$304,"<"&DATE(Parametros!$B$4,12+1,1)) -> 0 | H17: =SUMIFS(Comparativo!$S$5:$S$304,Comparativo!$B$5:$B$304,">="&DATE(Parametros!$B$4,12,1),Comparativo!$B$5:$B$304,"<"&DATE(Parametros!$B$4,12+1,1)) -> 0 | I17: =SUMIFS(Produccion!$E$5:$E$304,Produccion!$A$5:$A$304,Parametros!$B$4,Produccion!$B$5:$B$304,12) -> 0 | J17: =SUMIFS(Produccion!$F$5:$F$304,Produccion!$A$5:$A$304,Parametros!$B$4,Produccion!$B$5:$B$304,12) -> 0 | K17: =IF(I17=0,0,J17/I17) -> 0 | L17: =Consumos!W15 -> 0
A18: Total año | B18: =SUM(B6:B17) -> 9327.32 | C18: =SUM(C6:C17) -> 4017.32 | D18: =SUM(D6:D17) -> 5310 | E18: =IF(B18=0,0,C18/B18) -> 0.43070464 | F18: =IF(B18=0,0,D18/B18) -> 0.56929536 | G18: =SUM(G6:G17) -> 3 | H18: =SUM(H6:H17) -> 340 | I18: =SUM(I6:I17) -> 4160 | J18: =SUM(J6:J17) -> 283800 | K18: =IF(I18=0,0,J18/I18) -> 68.221154 | L18: =SUM(L6:L17) -> 1107.5
A21: Compras y ahorro por familia (año de análisis) | H21: Compras por centro de destino (año de análisis)
